2024-05-18 13:01:33,067 INFO    StreamThr :136876 [internal.py:wandb_internal():85] W&B internal server running at pid: 136876, started at: 2024-05-18 13:01:33.065973
2024-05-18 13:01:33,069 DEBUG   HandlerThread:136876 [handler.py:handle_request():158] handle_request: status
2024-05-18 13:01:33,074 INFO    WriterThread:136876 [datastore.py:open_for_write():87] open: ./wandb/run-20240518_130133-eie9xm86/run-eie9xm86.wandb
2024-05-18 13:01:33,075 DEBUG   SenderThread:136876 [sender.py:send():378] send: header
2024-05-18 13:01:33,077 DEBUG   SenderThread:136876 [sender.py:send():378] send: run
2024-05-18 13:01:33,080 INFO    SenderThread:136876 [sender.py:_setup_resume():748] checking resume status for None/SEED_test_loo/eie9xm86
2024-05-18 13:01:38,079 DEBUG   HandlerThread:136876 [handler.py:handle_request():158] handle_request: keepalive
2024-05-18 13:01:43,082 DEBUG   HandlerThread:136876 [handler.py:handle_request():158] handle_request: keepalive
2024-05-18 13:01:48,085 DEBUG   HandlerThread:136876 [handler.py:handle_request():158] handle_request: keepalive
2024-05-18 13:01:53,089 DEBUG   HandlerThread:136876 [handler.py:handle_request():158] handle_request: keepalive
2024-05-18 13:01:58,092 DEBUG   HandlerThread:136876 [handler.py:handle_request():158] handle_request: keepalive
2024-05-18 13:02:03,095 DEBUG   HandlerThread:136876 [handler.py:handle_request():158] handle_request: keepalive
2024-05-18 13:02:08,098 DEBUG   HandlerThread:136876 [handler.py:handle_request():158] handle_request: keepalive
2024-05-18 13:02:13,101 DEBUG   HandlerThread:136876 [handler.py:handle_request():158] handle_request: keepalive
2024-05-18 13:02:18,104 DEBUG   HandlerThread:136876 [handler.py:handle_request():158] handle_request: keepalive
2024-05-18 13:02:23,107 DEBUG   HandlerThread:136876 [handler.py:handle_request():158] handle_request: keepalive
2024-05-18 13:02:28,110 DEBUG   HandlerThread:136876 [handler.py:handle_request():158] handle_request: keepalive
2024-05-18 13:02:33,114 DEBUG   HandlerThread:136876 [handler.py:handle_request():158] handle_request: keepalive
2024-05-18 13:02:36,786 INFO    SenderThread:136876 [retry.py:__call__():172] Retry attempt failed:
Traceback (most recent call last):
  File "/home/ncclab/miniconda3/envs/att_model/lib/python3.11/site-packages/urllib3/connection.py", line 203, in _new_conn
    sock = connection.create_connection(
           ^^^^^^^^^^^^^^^^^^^^^^^^^^^^^
  File "/home/ncclab/miniconda3/envs/att_model/lib/python3.11/site-packages/urllib3/util/connection.py", line 85, in create_connection
    raise err
  File "/home/ncclab/miniconda3/envs/att_model/lib/python3.11/site-packages/urllib3/util/connection.py", line 73, in create_connection
    sock.connect(sa)
TimeoutError: timed out

The above exception was the direct cause of the following exception:

Traceback (most recent call last):
  File "/home/ncclab/miniconda3/envs/att_model/lib/python3.11/site-packages/urllib3/connectionpool.py", line 790, in urlopen
    response = self._make_request(
               ^^^^^^^^^^^^^^^^^^^
  File "/home/ncclab/miniconda3/envs/att_model/lib/python3.11/site-packages/urllib3/connectionpool.py", line 491, in _make_request
    raise new_e
  File "/home/ncclab/miniconda3/envs/att_model/lib/python3.11/site-packages/urllib3/connectionpool.py", line 467, in _make_request
    self._validate_conn(conn)
  File "/home/ncclab/miniconda3/envs/att_model/lib/python3.11/site-packages/urllib3/connectionpool.py", line 1096, in _validate_conn
    conn.connect()
  File "/home/ncclab/miniconda3/envs/att_model/lib/python3.11/site-packages/urllib3/connection.py", line 611, in connect
    self.sock = sock = self._new_conn()
                       ^^^^^^^^^^^^^^^^
  File "/home/ncclab/miniconda3/envs/att_model/lib/python3.11/site-packages/urllib3/connection.py", line 212, in _new_conn
    raise ConnectTimeoutError(
urllib3.exceptions.ConnectTimeoutError: (<urllib3.connection.HTTPSConnection object at 0x7f724c202450>, 'Connection to api.wandb.ai timed out. (connect timeout=20)')

The above exception was the direct cause of the following exception:

Traceback (most recent call last):
  File "/home/ncclab/miniconda3/envs/att_model/lib/python3.11/site-packages/requests/adapters.py", line 486, in send
    resp = conn.urlopen(
           ^^^^^^^^^^^^^
  File "/home/ncclab/miniconda3/envs/att_model/lib/python3.11/site-packages/urllib3/connectionpool.py", line 844, in urlopen
    retries = retries.increment(
              ^^^^^^^^^^^^^^^^^^
  File "/home/ncclab/miniconda3/envs/att_model/lib/python3.11/site-packages/urllib3/util/retry.py", line 515, in increment
    raise MaxRetryError(_pool, url, reason) from reason  # type: ignore[arg-type]
    ^^^^^^^^^^^^^^^^^^^^^^^^^^^^^^^^^^^^^^^^^^^^^^^^^^^
urllib3.exceptions.MaxRetryError: HTTPSConnectionPool(host='api.wandb.ai', port=443): Max retries exceeded with url: /graphql (Caused by ConnectTimeoutError(<urllib3.connection.HTTPSConnection object at 0x7f724c202450>, 'Connection to api.wandb.ai timed out. (connect timeout=20)'))

During handling of the above exception, another exception occurred:

Traceback (most recent call last):
  File "/home/ncclab/miniconda3/envs/att_model/lib/python3.11/site-packages/wandb/sdk/lib/retry.py", line 131, in __call__
    result = self._call_fn(*args, **kwargs)
             ^^^^^^^^^^^^^^^^^^^^^^^^^^^^^^
  File "/home/ncclab/miniconda3/envs/att_model/lib/python3.11/site-packages/wandb/sdk/internal/internal_api.py", line 340, in execute
    return self.client.execute(*args, **kwargs)  # type: ignore
           ^^^^^^^^^^^^^^^^^^^^^^^^^^^^^^^^^^^^
  File "/home/ncclab/miniconda3/envs/att_model/lib/python3.11/site-packages/wandb/vendor/gql-0.2.0/wandb_gql/client.py", line 52, in execute
    result = self._get_result(document, *args, **kwargs)
             ^^^^^^^^^^^^^^^^^^^^^^^^^^^^^^^^^^^^^^^^^^^
  File "/home/ncclab/miniconda3/envs/att_model/lib/python3.11/site-packages/wandb/vendor/gql-0.2.0/wandb_gql/client.py", line 60, in _get_result
    return self.transport.execute(document, *args, **kwargs)
           ^^^^^^^^^^^^^^^^^^^^^^^^^^^^^^^^^^^^^^^^^^^^^^^^^
  File "/home/ncclab/miniconda3/envs/att_model/lib/python3.11/site-packages/wandb/sdk/lib/gql_request.py", line 58, in execute
    request = self.session.post(self.url, **post_args)
              ^^^^^^^^^^^^^^^^^^^^^^^^^^^^^^^^^^^^^^^^
  File "/home/ncclab/miniconda3/envs/att_model/lib/python3.11/site-packages/requests/sessions.py", line 637, in post
    return self.request("POST", url, data=data, json=json, **kwargs)
           ^^^^^^^^^^^^^^^^^^^^^^^^^^^^^^^^^^^^^^^^^^^^^^^^^^^^^^^^^
  File "/home/ncclab/miniconda3/envs/att_model/lib/python3.11/site-packages/requests/sessions.py", line 589, in request
    resp = self.send(prep, **send_kwargs)
           ^^^^^^^^^^^^^^^^^^^^^^^^^^^^^^
  File "/home/ncclab/miniconda3/envs/att_model/lib/python3.11/site-packages/requests/sessions.py", line 703, in send
    r = adapter.send(request, **kwargs)
        ^^^^^^^^^^^^^^^^^^^^^^^^^^^^^^^
  File "/home/ncclab/miniconda3/envs/att_model/lib/python3.11/site-packages/requests/adapters.py", line 507, in send
    raise ConnectTimeout(e, request=request)
requests.exceptions.ConnectTimeout: HTTPSConnectionPool(host='api.wandb.ai', port=443): Max retries exceeded with url: /graphql (Caused by ConnectTimeoutError(<urllib3.connection.HTTPSConnection object at 0x7f724c202450>, 'Connection to api.wandb.ai timed out. (connect timeout=20)'))
2024-05-18 13:02:38,117 DEBUG   HandlerThread:136876 [handler.py:handle_request():158] handle_request: keepalive
2024-05-18 13:02:43,120 DEBUG   HandlerThread:136876 [handler.py:handle_request():158] handle_request: keepalive
2024-05-18 13:02:48,123 DEBUG   HandlerThread:136876 [handler.py:handle_request():158] handle_request: keepalive
2024-05-18 13:02:53,126 DEBUG   HandlerThread:136876 [handler.py:handle_request():158] handle_request: keepalive
2024-05-18 13:02:58,129 DEBUG   HandlerThread:136876 [handler.py:handle_request():158] handle_request: keepalive
2024-05-18 13:03:03,131 DEBUG   HandlerThread:136876 [handler.py:handle_request():158] handle_request: cancel
2024-05-18 13:03:03,132 DEBUG   HandlerThread:136876 [handler.py:handle_request():158] handle_request: cancel
2024-05-18 13:03:03,132 DEBUG   SenderThread:136876 [sender.py:send():387] Record cancelled: run
2024-05-18 13:03:03,132 DEBUG   HandlerThread:136876 [handler.py:handle_request():158] handle_request: status_report
2024-05-18 13:03:03,325 DEBUG   HandlerThread:136876 [handler.py:handle_request():158] handle_request: shutdown
2024-05-18 13:03:03,326 INFO    HandlerThread:136876 [handler.py:finish():882] shutting down handler
2024-05-18 13:03:04,133 INFO    SenderThread:136876 [sender.py:finish():1545] shutting down sender
2024-05-18 13:03:04,133 INFO    WriterThread:136876 [datastore.py:close():296] close: ./wandb/run-20240518_130133-eie9xm86/run-eie9xm86.wandb
