2024-05-18 14:39:15,633 INFO    StreamThr :137108 [internal.py:wandb_internal():85] W&B internal server running at pid: 137108, started at: 2024-05-18 14:39:15.632595
2024-05-18 14:39:15,637 DEBUG   HandlerThread:137108 [handler.py:handle_request():158] handle_request: status
2024-05-18 14:39:15,641 INFO    WriterThread:137108 [datastore.py:open_for_write():87] open: /home/ncclab/shenxinke/att_model/CLISA_Hydra/clisa_run/SEED/2024-05-18/14-39-09_run2/wandb/run-20240518_143915-xzpwue2k/run-xzpwue2k.wandb
2024-05-18 14:39:15,642 DEBUG   SenderThread:137108 [sender.py:send():378] send: header
2024-05-18 14:39:15,646 DEBUG   SenderThread:137108 [sender.py:send():378] send: run
2024-05-18 14:39:20,648 DEBUG   HandlerThread:137108 [handler.py:handle_request():158] handle_request: keepalive
2024-05-18 14:39:25,651 DEBUG   HandlerThread:137108 [handler.py:handle_request():158] handle_request: keepalive
2024-05-18 14:39:30,654 DEBUG   HandlerThread:137108 [handler.py:handle_request():158] handle_request: keepalive
2024-05-18 14:39:35,657 DEBUG   HandlerThread:137108 [handler.py:handle_request():158] handle_request: keepalive
2024-05-18 14:39:40,660 DEBUG   HandlerThread:137108 [handler.py:handle_request():158] handle_request: keepalive
2024-05-18 14:39:45,663 DEBUG   HandlerThread:137108 [handler.py:handle_request():158] handle_request: keepalive
2024-05-18 14:39:50,666 DEBUG   HandlerThread:137108 [handler.py:handle_request():158] handle_request: keepalive
2024-05-18 14:39:55,669 DEBUG   HandlerThread:137108 [handler.py:handle_request():158] handle_request: keepalive
2024-05-18 14:40:00,672 DEBUG   HandlerThread:137108 [handler.py:handle_request():158] handle_request: keepalive
2024-05-18 14:40:05,675 DEBUG   HandlerThread:137108 [handler.py:handle_request():158] handle_request: keepalive
2024-05-18 14:40:10,678 DEBUG   HandlerThread:137108 [handler.py:handle_request():158] handle_request: keepalive
2024-05-18 14:40:15,682 DEBUG   HandlerThread:137108 [handler.py:handle_request():158] handle_request: keepalive
2024-05-18 14:40:19,259 INFO    SenderThread:137108 [retry.py:__call__():172] Retry attempt failed:
Traceback (most recent call last):
  File "/home/ncclab/miniconda3/envs/att_model/lib/python3.11/site-packages/urllib3/connection.py", line 203, in _new_conn
    sock = connection.create_connection(
           ^^^^^^^^^^^^^^^^^^^^^^^^^^^^^
  File "/home/ncclab/miniconda3/envs/att_model/lib/python3.11/site-packages/urllib3/util/connection.py", line 85, in create_connection
    raise err
  File "/home/ncclab/miniconda3/envs/att_model/lib/python3.11/site-packages/urllib3/util/connection.py", line 73, in create_connection
    sock.connect(sa)
TimeoutError: timed out

The above exception was the direct cause of the following exception:

Traceback (most recent call last):
  File "/home/ncclab/miniconda3/envs/att_model/lib/python3.11/site-packages/urllib3/connectionpool.py", line 790, in urlopen
    response = self._make_request(
               ^^^^^^^^^^^^^^^^^^^
  File "/home/ncclab/miniconda3/envs/att_model/lib/python3.11/site-packages/urllib3/connectionpool.py", line 491, in _make_request
    raise new_e
  File "/home/ncclab/miniconda3/envs/att_model/lib/python3.11/site-packages/urllib3/connectionpool.py", line 467, in _make_request
    self._validate_conn(conn)
  File "/home/ncclab/miniconda3/envs/att_model/lib/python3.11/site-packages/urllib3/connectionpool.py", line 1096, in _validate_conn
    conn.connect()
  File "/home/ncclab/miniconda3/envs/att_model/lib/python3.11/site-packages/urllib3/connection.py", line 611, in connect
    self.sock = sock = self._new_conn()
                       ^^^^^^^^^^^^^^^^
  File "/home/ncclab/miniconda3/envs/att_model/lib/python3.11/site-packages/urllib3/connection.py", line 212, in _new_conn
    raise ConnectTimeoutError(
urllib3.exceptions.ConnectTimeoutError: (<urllib3.connection.HTTPSConnection object at 0x7fc610201990>, 'Connection to api.wandb.ai timed out. (connect timeout=20)')

The above exception was the direct cause of the following exception:

Traceback (most recent call last):
  File "/home/ncclab/miniconda3/envs/att_model/lib/python3.11/site-packages/requests/adapters.py", line 486, in send
    resp = conn.urlopen(
           ^^^^^^^^^^^^^
  File "/home/ncclab/miniconda3/envs/att_model/lib/python3.11/site-packages/urllib3/connectionpool.py", line 844, in urlopen
    retries = retries.increment(
              ^^^^^^^^^^^^^^^^^^
  File "/home/ncclab/miniconda3/envs/att_model/lib/python3.11/site-packages/urllib3/util/retry.py", line 515, in increment
    raise MaxRetryError(_pool, url, reason) from reason  # type: ignore[arg-type]
    ^^^^^^^^^^^^^^^^^^^^^^^^^^^^^^^^^^^^^^^^^^^^^^^^^^^
urllib3.exceptions.MaxRetryError: HTTPSConnectionPool(host='api.wandb.ai', port=443): Max retries exceeded with url: /graphql (Caused by ConnectTimeoutError(<urllib3.connection.HTTPSConnection object at 0x7fc610201990>, 'Connection to api.wandb.ai timed out. (connect timeout=20)'))

During handling of the above exception, another exception occurred:

Traceback (most recent call last):
  File "/home/ncclab/miniconda3/envs/att_model/lib/python3.11/site-packages/wandb/sdk/lib/retry.py", line 131, in __call__
    result = self._call_fn(*args, **kwargs)
             ^^^^^^^^^^^^^^^^^^^^^^^^^^^^^^
  File "/home/ncclab/miniconda3/envs/att_model/lib/python3.11/site-packages/wandb/sdk/internal/internal_api.py", line 340, in execute
    return self.client.execute(*args, **kwargs)  # type: ignore
           ^^^^^^^^^^^^^^^^^^^^^^^^^^^^^^^^^^^^
  File "/home/ncclab/miniconda3/envs/att_model/lib/python3.11/site-packages/wandb/vendor/gql-0.2.0/wandb_gql/client.py", line 52, in execute
    result = self._get_result(document, *args, **kwargs)
             ^^^^^^^^^^^^^^^^^^^^^^^^^^^^^^^^^^^^^^^^^^^
  File "/home/ncclab/miniconda3/envs/att_model/lib/python3.11/site-packages/wandb/vendor/gql-0.2.0/wandb_gql/client.py", line 60, in _get_result
    return self.transport.execute(document, *args, **kwargs)
           ^^^^^^^^^^^^^^^^^^^^^^^^^^^^^^^^^^^^^^^^^^^^^^^^^
  File "/home/ncclab/miniconda3/envs/att_model/lib/python3.11/site-packages/wandb/sdk/lib/gql_request.py", line 58, in execute
    request = self.session.post(self.url, **post_args)
              ^^^^^^^^^^^^^^^^^^^^^^^^^^^^^^^^^^^^^^^^
  File "/home/ncclab/miniconda3/envs/att_model/lib/python3.11/site-packages/requests/sessions.py", line 637, in post
    return self.request("POST", url, data=data, json=json, **kwargs)
           ^^^^^^^^^^^^^^^^^^^^^^^^^^^^^^^^^^^^^^^^^^^^^^^^^^^^^^^^^
  File "/home/ncclab/miniconda3/envs/att_model/lib/python3.11/site-packages/requests/sessions.py", line 589, in request
    resp = self.send(prep, **send_kwargs)
           ^^^^^^^^^^^^^^^^^^^^^^^^^^^^^^
  File "/home/ncclab/miniconda3/envs/att_model/lib/python3.11/site-packages/requests/sessions.py", line 703, in send
    r = adapter.send(request, **kwargs)
        ^^^^^^^^^^^^^^^^^^^^^^^^^^^^^^^
  File "/home/ncclab/miniconda3/envs/att_model/lib/python3.11/site-packages/requests/adapters.py", line 507, in send
    raise ConnectTimeout(e, request=request)
requests.exceptions.ConnectTimeout: HTTPSConnectionPool(host='api.wandb.ai', port=443): Max retries exceeded with url: /graphql (Caused by ConnectTimeoutError(<urllib3.connection.HTTPSConnection object at 0x7fc610201990>, 'Connection to api.wandb.ai timed out. (connect timeout=20)'))
2024-05-18 14:40:20,685 DEBUG   HandlerThread:137108 [handler.py:handle_request():158] handle_request: keepalive
2024-05-18 14:40:25,688 DEBUG   HandlerThread:137108 [handler.py:handle_request():158] handle_request: keepalive
2024-05-18 14:40:30,691 DEBUG   HandlerThread:137108 [handler.py:handle_request():158] handle_request: keepalive
2024-05-18 14:40:35,695 DEBUG   HandlerThread:137108 [handler.py:handle_request():158] handle_request: keepalive
2024-05-18 14:40:40,697 DEBUG   HandlerThread:137108 [handler.py:handle_request():158] handle_request: keepalive
2024-05-18 14:40:45,701 DEBUG   HandlerThread:137108 [handler.py:handle_request():158] handle_request: cancel
2024-05-18 14:40:45,701 DEBUG   HandlerThread:137108 [handler.py:handle_request():158] handle_request: cancel
2024-05-18 14:40:45,701 DEBUG   SenderThread:137108 [sender.py:send():387] Record cancelled: run
2024-05-18 14:40:45,703 DEBUG   HandlerThread:137108 [handler.py:handle_request():158] handle_request: status_report
2024-05-18 14:40:45,889 DEBUG   HandlerThread:137108 [handler.py:handle_request():158] handle_request: shutdown
2024-05-18 14:40:45,890 INFO    HandlerThread:137108 [handler.py:finish():882] shutting down handler
2024-05-18 14:40:46,703 INFO    SenderThread:137108 [sender.py:finish():1545] shutting down sender
2024-05-18 14:40:46,704 INFO    WriterThread:137108 [datastore.py:close():296] close: /home/ncclab/shenxinke/att_model/CLISA_Hydra/clisa_run/SEED/2024-05-18/14-39-09_run2/wandb/run-20240518_143915-xzpwue2k/run-xzpwue2k.wandb
