2024-05-18 12:55:57,435 INFO    StreamThr :136799 [internal.py:wandb_internal():85] W&B internal server running at pid: 136799, started at: 2024-05-18 12:55:57.433861
2024-05-18 12:55:57,438 DEBUG   HandlerThread:136799 [handler.py:handle_request():158] handle_request: status
2024-05-18 12:55:57,442 INFO    WriterThread:136799 [datastore.py:open_for_write():87] open: ./wandb/run-20240518_125557-nmhzru1o/run-nmhzru1o.wandb
2024-05-18 12:55:57,443 DEBUG   SenderThread:136799 [sender.py:send():378] send: header
2024-05-18 12:55:57,447 DEBUG   SenderThread:136799 [sender.py:send():378] send: run
2024-05-18 12:55:57,450 INFO    SenderThread:136799 [sender.py:_setup_resume():748] checking resume status for None/SEED_test_loo/nmhzru1o
2024-05-18 12:56:02,450 DEBUG   HandlerThread:136799 [handler.py:handle_request():158] handle_request: keepalive
2024-05-18 12:56:07,453 DEBUG   HandlerThread:136799 [handler.py:handle_request():158] handle_request: keepalive
2024-05-18 12:56:12,456 DEBUG   HandlerThread:136799 [handler.py:handle_request():158] handle_request: keepalive
2024-05-18 12:56:17,459 DEBUG   HandlerThread:136799 [handler.py:handle_request():158] handle_request: keepalive
2024-05-18 12:56:22,462 DEBUG   HandlerThread:136799 [handler.py:handle_request():158] handle_request: keepalive
2024-05-18 12:56:27,465 DEBUG   HandlerThread:136799 [handler.py:handle_request():158] handle_request: keepalive
2024-05-18 12:56:32,469 DEBUG   HandlerThread:136799 [handler.py:handle_request():158] handle_request: keepalive
2024-05-18 12:56:37,471 DEBUG   HandlerThread:136799 [handler.py:handle_request():158] handle_request: keepalive
2024-05-18 12:56:42,474 DEBUG   HandlerThread:136799 [handler.py:handle_request():158] handle_request: keepalive
2024-05-18 12:56:47,477 DEBUG   HandlerThread:136799 [handler.py:handle_request():158] handle_request: keepalive
2024-05-18 12:56:52,480 DEBUG   HandlerThread:136799 [handler.py:handle_request():158] handle_request: keepalive
2024-05-18 12:56:57,483 DEBUG   HandlerThread:136799 [handler.py:handle_request():158] handle_request: keepalive
2024-05-18 12:57:00,994 INFO    SenderThread:136799 [retry.py:__call__():172] Retry attempt failed:
Traceback (most recent call last):
  File "/home/ncclab/miniconda3/envs/att_model/lib/python3.11/site-packages/urllib3/connection.py", line 203, in _new_conn
    sock = connection.create_connection(
           ^^^^^^^^^^^^^^^^^^^^^^^^^^^^^
  File "/home/ncclab/miniconda3/envs/att_model/lib/python3.11/site-packages/urllib3/util/connection.py", line 85, in create_connection
    raise err
  File "/home/ncclab/miniconda3/envs/att_model/lib/python3.11/site-packages/urllib3/util/connection.py", line 73, in create_connection
    sock.connect(sa)
TimeoutError: timed out

The above exception was the direct cause of the following exception:

Traceback (most recent call last):
  File "/home/ncclab/miniconda3/envs/att_model/lib/python3.11/site-packages/urllib3/connectionpool.py", line 790, in urlopen
    response = self._make_request(
               ^^^^^^^^^^^^^^^^^^^
  File "/home/ncclab/miniconda3/envs/att_model/lib/python3.11/site-packages/urllib3/connectionpool.py", line 491, in _make_request
    raise new_e
  File "/home/ncclab/miniconda3/envs/att_model/lib/python3.11/site-packages/urllib3/connectionpool.py", line 467, in _make_request
    self._validate_conn(conn)
  File "/home/ncclab/miniconda3/envs/att_model/lib/python3.11/site-packages/urllib3/connectionpool.py", line 1096, in _validate_conn
    conn.connect()
  File "/home/ncclab/miniconda3/envs/att_model/lib/python3.11/site-packages/urllib3/connection.py", line 611, in connect
    self.sock = sock = self._new_conn()
                       ^^^^^^^^^^^^^^^^
  File "/home/ncclab/miniconda3/envs/att_model/lib/python3.11/site-packages/urllib3/connection.py", line 212, in _new_conn
    raise ConnectTimeoutError(
urllib3.exceptions.ConnectTimeoutError: (<urllib3.connection.HTTPSConnection object at 0x7f71c83fe190>, 'Connection to api.wandb.ai timed out. (connect timeout=20)')

The above exception was the direct cause of the following exception:

Traceback (most recent call last):
  File "/home/ncclab/miniconda3/envs/att_model/lib/python3.11/site-packages/requests/adapters.py", line 486, in send
    resp = conn.urlopen(
           ^^^^^^^^^^^^^
  File "/home/ncclab/miniconda3/envs/att_model/lib/python3.11/site-packages/urllib3/connectionpool.py", line 844, in urlopen
    retries = retries.increment(
              ^^^^^^^^^^^^^^^^^^
  File "/home/ncclab/miniconda3/envs/att_model/lib/python3.11/site-packages/urllib3/util/retry.py", line 515, in increment
    raise MaxRetryError(_pool, url, reason) from reason  # type: ignore[arg-type]
    ^^^^^^^^^^^^^^^^^^^^^^^^^^^^^^^^^^^^^^^^^^^^^^^^^^^
urllib3.exceptions.MaxRetryError: HTTPSConnectionPool(host='api.wandb.ai', port=443): Max retries exceeded with url: /graphql (Caused by ConnectTimeoutError(<urllib3.connection.HTTPSConnection object at 0x7f71c83fe190>, 'Connection to api.wandb.ai timed out. (connect timeout=20)'))

During handling of the above exception, another exception occurred:

Traceback (most recent call last):
  File "/home/ncclab/miniconda3/envs/att_model/lib/python3.11/site-packages/wandb/sdk/lib/retry.py", line 131, in __call__
    result = self._call_fn(*args, **kwargs)
             ^^^^^^^^^^^^^^^^^^^^^^^^^^^^^^
  File "/home/ncclab/miniconda3/envs/att_model/lib/python3.11/site-packages/wandb/sdk/internal/internal_api.py", line 340, in execute
    return self.client.execute(*args, **kwargs)  # type: ignore
           ^^^^^^^^^^^^^^^^^^^^^^^^^^^^^^^^^^^^
  File "/home/ncclab/miniconda3/envs/att_model/lib/python3.11/site-packages/wandb/vendor/gql-0.2.0/wandb_gql/client.py", line 52, in execute
    result = self._get_result(document, *args, **kwargs)
             ^^^^^^^^^^^^^^^^^^^^^^^^^^^^^^^^^^^^^^^^^^^
  File "/home/ncclab/miniconda3/envs/att_model/lib/python3.11/site-packages/wandb/vendor/gql-0.2.0/wandb_gql/client.py", line 60, in _get_result
    return self.transport.execute(document, *args, **kwargs)
           ^^^^^^^^^^^^^^^^^^^^^^^^^^^^^^^^^^^^^^^^^^^^^^^^^
  File "/home/ncclab/miniconda3/envs/att_model/lib/python3.11/site-packages/wandb/sdk/lib/gql_request.py", line 58, in execute
    request = self.session.post(self.url, **post_args)
              ^^^^^^^^^^^^^^^^^^^^^^^^^^^^^^^^^^^^^^^^
  File "/home/ncclab/miniconda3/envs/att_model/lib/python3.11/site-packages/requests/sessions.py", line 637, in post
    return self.request("POST", url, data=data, json=json, **kwargs)
           ^^^^^^^^^^^^^^^^^^^^^^^^^^^^^^^^^^^^^^^^^^^^^^^^^^^^^^^^^
  File "/home/ncclab/miniconda3/envs/att_model/lib/python3.11/site-packages/requests/sessions.py", line 589, in request
    resp = self.send(prep, **send_kwargs)
           ^^^^^^^^^^^^^^^^^^^^^^^^^^^^^^
  File "/home/ncclab/miniconda3/envs/att_model/lib/python3.11/site-packages/requests/sessions.py", line 703, in send
    r = adapter.send(request, **kwargs)
        ^^^^^^^^^^^^^^^^^^^^^^^^^^^^^^^
  File "/home/ncclab/miniconda3/envs/att_model/lib/python3.11/site-packages/requests/adapters.py", line 507, in send
    raise ConnectTimeout(e, request=request)
requests.exceptions.ConnectTimeout: HTTPSConnectionPool(host='api.wandb.ai', port=443): Max retries exceeded with url: /graphql (Caused by ConnectTimeoutError(<urllib3.connection.HTTPSConnection object at 0x7f71c83fe190>, 'Connection to api.wandb.ai timed out. (connect timeout=20)'))
2024-05-18 12:57:02,486 DEBUG   HandlerThread:136799 [handler.py:handle_request():158] handle_request: keepalive
2024-05-18 12:57:07,489 DEBUG   HandlerThread:136799 [handler.py:handle_request():158] handle_request: keepalive
2024-05-18 12:57:12,492 DEBUG   HandlerThread:136799 [handler.py:handle_request():158] handle_request: keepalive
2024-05-18 12:57:17,495 DEBUG   HandlerThread:136799 [handler.py:handle_request():158] handle_request: keepalive
2024-05-18 12:57:22,498 DEBUG   HandlerThread:136799 [handler.py:handle_request():158] handle_request: keepalive
2024-05-18 12:57:27,501 DEBUG   HandlerThread:136799 [handler.py:handle_request():158] handle_request: cancel
2024-05-18 12:57:27,501 DEBUG   HandlerThread:136799 [handler.py:handle_request():158] handle_request: cancel
2024-05-18 12:57:27,502 DEBUG   SenderThread:136799 [sender.py:send():387] Record cancelled: run
2024-05-18 12:57:27,502 DEBUG   HandlerThread:136799 [handler.py:handle_request():158] handle_request: status_report
2024-05-18 12:57:27,765 DEBUG   HandlerThread:136799 [handler.py:handle_request():158] handle_request: shutdown
2024-05-18 12:57:27,765 INFO    HandlerThread:136799 [handler.py:finish():882] shutting down handler
2024-05-18 12:57:28,503 INFO    SenderThread:136799 [sender.py:finish():1545] shutting down sender
2024-05-18 12:57:28,503 INFO    WriterThread:136799 [datastore.py:close():296] close: ./wandb/run-20240518_125557-nmhzru1o/run-nmhzru1o.wandb
