2024-05-13 14:20:54,526 INFO    StreamThr :19377 [internal.py:wandb_internal():86] W&B internal server running at pid: 19377, started at: 2024-05-13 14:20:54.525449
2024-05-13 14:20:54,529 DEBUG   HandlerThread:19377 [handler.py:handle_request():146] handle_request: status
2024-05-13 14:20:54,533 INFO    WriterThread:19377 [datastore.py:open_for_write():87] open: ./wandb/run-20240513_142054-k6q8gwft/run-k6q8gwft.wandb
2024-05-13 14:20:54,534 DEBUG   SenderThread:19377 [sender.py:send():379] send: header
2024-05-13 14:20:54,536 DEBUG   SenderThread:19377 [sender.py:send():379] send: run
2024-05-13 14:20:54,539 INFO    SenderThread:19377 [sender.py:_setup_resume():749] checking resume status for None/SEED_test/k6q8gwft
2024-05-13 14:20:59,538 DEBUG   HandlerThread:19377 [handler.py:handle_request():146] handle_request: keepalive
2024-05-13 14:21:04,541 DEBUG   HandlerThread:19377 [handler.py:handle_request():146] handle_request: keepalive
2024-05-13 14:21:09,544 DEBUG   HandlerThread:19377 [handler.py:handle_request():146] handle_request: keepalive
2024-05-13 14:21:14,546 DEBUG   HandlerThread:19377 [handler.py:handle_request():146] handle_request: keepalive
2024-05-13 14:21:19,549 DEBUG   HandlerThread:19377 [handler.py:handle_request():146] handle_request: keepalive
2024-05-13 14:21:24,552 DEBUG   HandlerThread:19377 [handler.py:handle_request():146] handle_request: keepalive
2024-05-13 14:21:29,555 DEBUG   HandlerThread:19377 [handler.py:handle_request():146] handle_request: keepalive
2024-05-13 14:21:34,558 DEBUG   HandlerThread:19377 [handler.py:handle_request():146] handle_request: keepalive
2024-05-13 14:21:39,561 DEBUG   HandlerThread:19377 [handler.py:handle_request():146] handle_request: keepalive
2024-05-13 14:21:44,565 DEBUG   HandlerThread:19377 [handler.py:handle_request():146] handle_request: keepalive
2024-05-13 14:21:49,568 DEBUG   HandlerThread:19377 [handler.py:handle_request():146] handle_request: keepalive
2024-05-13 14:21:54,571 DEBUG   HandlerThread:19377 [handler.py:handle_request():146] handle_request: keepalive
2024-05-13 14:21:59,304 INFO    SenderThread:19377 [retry.py:__call__():172] Retry attempt failed:
Traceback (most recent call last):
  File "/home/ncclab/miniconda3/envs/att_model/lib/python3.11/site-packages/urllib3/connectionpool.py", line 536, in _make_request
    response = conn.getresponse()
               ^^^^^^^^^^^^^^^^^^
  File "/home/ncclab/miniconda3/envs/att_model/lib/python3.11/site-packages/urllib3/connection.py", line 461, in getresponse
    httplib_response = super().getresponse()
                       ^^^^^^^^^^^^^^^^^^^^^
  File "/home/ncclab/miniconda3/envs/att_model/lib/python3.11/http/client.py", line 1375, in getresponse
    response.begin()
  File "/home/ncclab/miniconda3/envs/att_model/lib/python3.11/http/client.py", line 318, in begin
    version, status, reason = self._read_status()
                              ^^^^^^^^^^^^^^^^^^^
  File "/home/ncclab/miniconda3/envs/att_model/lib/python3.11/http/client.py", line 279, in _read_status
    line = str(self.fp.readline(_MAXLINE + 1), "iso-8859-1")
               ^^^^^^^^^^^^^^^^^^^^^^^^^^^^^^
  File "/home/ncclab/miniconda3/envs/att_model/lib/python3.11/socket.py", line 706, in readinto
    return self._sock.recv_into(b)
           ^^^^^^^^^^^^^^^^^^^^^^^
  File "/home/ncclab/miniconda3/envs/att_model/lib/python3.11/ssl.py", line 1278, in recv_into
    return self.read(nbytes, buffer)
           ^^^^^^^^^^^^^^^^^^^^^^^^^
  File "/home/ncclab/miniconda3/envs/att_model/lib/python3.11/ssl.py", line 1134, in read
    return self._sslobj.read(len, buffer)
           ^^^^^^^^^^^^^^^^^^^^^^^^^^^^^^
TimeoutError: The read operation timed out

The above exception was the direct cause of the following exception:

Traceback (most recent call last):
  File "/home/ncclab/miniconda3/envs/att_model/lib/python3.11/site-packages/requests/adapters.py", line 486, in send
    resp = conn.urlopen(
           ^^^^^^^^^^^^^
  File "/home/ncclab/miniconda3/envs/att_model/lib/python3.11/site-packages/urllib3/connectionpool.py", line 844, in urlopen
    retries = retries.increment(
              ^^^^^^^^^^^^^^^^^^
  File "/home/ncclab/miniconda3/envs/att_model/lib/python3.11/site-packages/urllib3/util/retry.py", line 470, in increment
    raise reraise(type(error), error, _stacktrace)
          ^^^^^^^^^^^^^^^^^^^^^^^^^^^^^^^^^^^^^^^^
  File "/home/ncclab/miniconda3/envs/att_model/lib/python3.11/site-packages/urllib3/util/util.py", line 39, in reraise
    raise value
  File "/home/ncclab/miniconda3/envs/att_model/lib/python3.11/site-packages/urllib3/connectionpool.py", line 790, in urlopen
    response = self._make_request(
               ^^^^^^^^^^^^^^^^^^^
  File "/home/ncclab/miniconda3/envs/att_model/lib/python3.11/site-packages/urllib3/connectionpool.py", line 538, in _make_request
    self._raise_timeout(err=e, url=url, timeout_value=read_timeout)
  File "/home/ncclab/miniconda3/envs/att_model/lib/python3.11/site-packages/urllib3/connectionpool.py", line 370, in _raise_timeout
    raise ReadTimeoutError(
urllib3.exceptions.ReadTimeoutError: HTTPSConnectionPool(host='api.wandb.ai', port=443): Read timed out. (read timeout=20)

During handling of the above exception, another exception occurred:

Traceback (most recent call last):
  File "/home/ncclab/miniconda3/envs/att_model/lib/python3.11/site-packages/wandb/sdk/lib/retry.py", line 131, in __call__
    result = self._call_fn(*args, **kwargs)
             ^^^^^^^^^^^^^^^^^^^^^^^^^^^^^^
  File "/home/ncclab/miniconda3/envs/att_model/lib/python3.11/site-packages/wandb/sdk/internal/internal_api.py", line 369, in execute
    return self.client.execute(*args, **kwargs)  # type: ignore
           ^^^^^^^^^^^^^^^^^^^^^^^^^^^^^^^^^^^^
  File "/home/ncclab/miniconda3/envs/att_model/lib/python3.11/site-packages/wandb/vendor/gql-0.2.0/wandb_gql/client.py", line 52, in execute
    result = self._get_result(document, *args, **kwargs)
             ^^^^^^^^^^^^^^^^^^^^^^^^^^^^^^^^^^^^^^^^^^^
  File "/home/ncclab/miniconda3/envs/att_model/lib/python3.11/site-packages/wandb/vendor/gql-0.2.0/wandb_gql/client.py", line 60, in _get_result
    return self.transport.execute(document, *args, **kwargs)
           ^^^^^^^^^^^^^^^^^^^^^^^^^^^^^^^^^^^^^^^^^^^^^^^^^
  File "/home/ncclab/miniconda3/envs/att_model/lib/python3.11/site-packages/wandb/sdk/lib/gql_request.py", line 58, in execute
    request = self.session.post(self.url, **post_args)
              ^^^^^^^^^^^^^^^^^^^^^^^^^^^^^^^^^^^^^^^^
  File "/home/ncclab/miniconda3/envs/att_model/lib/python3.11/site-packages/requests/sessions.py", line 637, in post
    return self.request("POST", url, data=data, json=json, **kwargs)
           ^^^^^^^^^^^^^^^^^^^^^^^^^^^^^^^^^^^^^^^^^^^^^^^^^^^^^^^^^
  File "/home/ncclab/miniconda3/envs/att_model/lib/python3.11/site-packages/requests/sessions.py", line 589, in request
    resp = self.send(prep, **send_kwargs)
           ^^^^^^^^^^^^^^^^^^^^^^^^^^^^^^
  File "/home/ncclab/miniconda3/envs/att_model/lib/python3.11/site-packages/requests/sessions.py", line 703, in send
    r = adapter.send(request, **kwargs)
        ^^^^^^^^^^^^^^^^^^^^^^^^^^^^^^^
  File "/home/ncclab/miniconda3/envs/att_model/lib/python3.11/site-packages/requests/adapters.py", line 532, in send
    raise ReadTimeout(e, request=request)
requests.exceptions.ReadTimeout: HTTPSConnectionPool(host='api.wandb.ai', port=443): Read timed out. (read timeout=20)
2024-05-13 14:21:59,574 DEBUG   HandlerThread:19377 [handler.py:handle_request():146] handle_request: keepalive
2024-05-13 14:22:04,577 DEBUG   HandlerThread:19377 [handler.py:handle_request():146] handle_request: keepalive
2024-05-13 14:22:09,580 DEBUG   HandlerThread:19377 [handler.py:handle_request():146] handle_request: keepalive
2024-05-13 14:22:14,582 DEBUG   HandlerThread:19377 [handler.py:handle_request():146] handle_request: keepalive
2024-05-13 14:22:19,585 DEBUG   HandlerThread:19377 [handler.py:handle_request():146] handle_request: keepalive
2024-05-13 14:22:24,589 DEBUG   HandlerThread:19377 [handler.py:handle_request():146] handle_request: cancel
2024-05-13 14:22:24,589 DEBUG   HandlerThread:19377 [handler.py:handle_request():146] handle_request: cancel
2024-05-13 14:22:24,589 DEBUG   SenderThread:19377 [sender.py:send():388] Record cancelled: run
2024-05-13 14:22:24,590 DEBUG   HandlerThread:19377 [handler.py:handle_request():146] handle_request: status_report
2024-05-13 14:22:25,012 DEBUG   HandlerThread:19377 [handler.py:handle_request():146] handle_request: shutdown
2024-05-13 14:22:25,012 INFO    HandlerThread:19377 [handler.py:finish():866] shutting down handler
2024-05-13 14:22:25,590 INFO    SenderThread:19377 [sender.py:finish():1546] shutting down sender
2024-05-13 14:22:25,591 INFO    WriterThread:19377 [datastore.py:close():296] close: ./wandb/run-20240513_142054-k6q8gwft/run-k6q8gwft.wandb
