2024-05-14 16:42:43,773 INFO    StreamThr :29835 [internal.py:wandb_internal():86] W&B internal server running at pid: 29835, started at: 2024-05-14 16:42:43.772096
2024-05-14 16:42:43,776 DEBUG   HandlerThread:29835 [handler.py:handle_request():146] handle_request: status
2024-05-14 16:42:43,779 INFO    WriterThread:29835 [datastore.py:open_for_write():87] open: ./wandb/run-20240514_164243-kaofva3p/run-kaofva3p.wandb
2024-05-14 16:42:43,780 DEBUG   SenderThread:29835 [sender.py:send():379] send: header
2024-05-14 16:42:43,783 DEBUG   SenderThread:29835 [sender.py:send():379] send: run
2024-05-14 16:42:43,787 INFO    SenderThread:29835 [sender.py:_setup_resume():749] checking resume status for None/SEED_test/kaofva3p
2024-05-14 16:42:48,786 DEBUG   HandlerThread:29835 [handler.py:handle_request():146] handle_request: keepalive
2024-05-14 16:42:53,790 DEBUG   HandlerThread:29835 [handler.py:handle_request():146] handle_request: keepalive
2024-05-14 16:42:58,793 DEBUG   HandlerThread:29835 [handler.py:handle_request():146] handle_request: keepalive
2024-05-14 16:43:03,796 DEBUG   HandlerThread:29835 [handler.py:handle_request():146] handle_request: keepalive
2024-05-14 16:43:08,800 DEBUG   HandlerThread:29835 [handler.py:handle_request():146] handle_request: keepalive
2024-05-14 16:43:13,803 DEBUG   HandlerThread:29835 [handler.py:handle_request():146] handle_request: keepalive
2024-05-14 16:43:18,806 DEBUG   HandlerThread:29835 [handler.py:handle_request():146] handle_request: keepalive
2024-05-14 16:43:23,809 DEBUG   HandlerThread:29835 [handler.py:handle_request():146] handle_request: keepalive
2024-05-14 16:43:28,812 DEBUG   HandlerThread:29835 [handler.py:handle_request():146] handle_request: keepalive
2024-05-14 16:43:33,815 DEBUG   HandlerThread:29835 [handler.py:handle_request():146] handle_request: keepalive
2024-05-14 16:43:38,818 DEBUG   HandlerThread:29835 [handler.py:handle_request():146] handle_request: keepalive
2024-05-14 16:43:43,821 DEBUG   HandlerThread:29835 [handler.py:handle_request():146] handle_request: keepalive
2024-05-14 16:43:48,496 INFO    SenderThread:29835 [retry.py:__call__():172] Retry attempt failed:
Traceback (most recent call last):
  File "/home/ncclab/miniconda3/envs/att_model/lib/python3.11/site-packages/urllib3/connectionpool.py", line 536, in _make_request
    response = conn.getresponse()
               ^^^^^^^^^^^^^^^^^^
  File "/home/ncclab/miniconda3/envs/att_model/lib/python3.11/site-packages/urllib3/connection.py", line 461, in getresponse
    httplib_response = super().getresponse()
                       ^^^^^^^^^^^^^^^^^^^^^
  File "/home/ncclab/miniconda3/envs/att_model/lib/python3.11/http/client.py", line 1375, in getresponse
    response.begin()
  File "/home/ncclab/miniconda3/envs/att_model/lib/python3.11/http/client.py", line 318, in begin
    version, status, reason = self._read_status()
                              ^^^^^^^^^^^^^^^^^^^
  File "/home/ncclab/miniconda3/envs/att_model/lib/python3.11/http/client.py", line 279, in _read_status
    line = str(self.fp.readline(_MAXLINE + 1), "iso-8859-1")
               ^^^^^^^^^^^^^^^^^^^^^^^^^^^^^^
  File "/home/ncclab/miniconda3/envs/att_model/lib/python3.11/socket.py", line 706, in readinto
    return self._sock.recv_into(b)
           ^^^^^^^^^^^^^^^^^^^^^^^
  File "/home/ncclab/miniconda3/envs/att_model/lib/python3.11/ssl.py", line 1278, in recv_into
    return self.read(nbytes, buffer)
           ^^^^^^^^^^^^^^^^^^^^^^^^^
  File "/home/ncclab/miniconda3/envs/att_model/lib/python3.11/ssl.py", line 1134, in read
    return self._sslobj.read(len, buffer)
           ^^^^^^^^^^^^^^^^^^^^^^^^^^^^^^
TimeoutError: The read operation timed out

The above exception was the direct cause of the following exception:

Traceback (most recent call last):
  File "/home/ncclab/miniconda3/envs/att_model/lib/python3.11/site-packages/requests/adapters.py", line 486, in send
    resp = conn.urlopen(
           ^^^^^^^^^^^^^
  File "/home/ncclab/miniconda3/envs/att_model/lib/python3.11/site-packages/urllib3/connectionpool.py", line 844, in urlopen
    retries = retries.increment(
              ^^^^^^^^^^^^^^^^^^
  File "/home/ncclab/miniconda3/envs/att_model/lib/python3.11/site-packages/urllib3/util/retry.py", line 470, in increment
    raise reraise(type(error), error, _stacktrace)
          ^^^^^^^^^^^^^^^^^^^^^^^^^^^^^^^^^^^^^^^^
  File "/home/ncclab/miniconda3/envs/att_model/lib/python3.11/site-packages/urllib3/util/util.py", line 39, in reraise
    raise value
  File "/home/ncclab/miniconda3/envs/att_model/lib/python3.11/site-packages/urllib3/connectionpool.py", line 790, in urlopen
    response = self._make_request(
               ^^^^^^^^^^^^^^^^^^^
  File "/home/ncclab/miniconda3/envs/att_model/lib/python3.11/site-packages/urllib3/connectionpool.py", line 538, in _make_request
    self._raise_timeout(err=e, url=url, timeout_value=read_timeout)
  File "/home/ncclab/miniconda3/envs/att_model/lib/python3.11/site-packages/urllib3/connectionpool.py", line 370, in _raise_timeout
    raise ReadTimeoutError(
urllib3.exceptions.ReadTimeoutError: HTTPSConnectionPool(host='api.wandb.ai', port=443): Read timed out. (read timeout=20)

During handling of the above exception, another exception occurred:

Traceback (most recent call last):
  File "/home/ncclab/miniconda3/envs/att_model/lib/python3.11/site-packages/wandb/sdk/lib/retry.py", line 131, in __call__
    result = self._call_fn(*args, **kwargs)
             ^^^^^^^^^^^^^^^^^^^^^^^^^^^^^^
  File "/home/ncclab/miniconda3/envs/att_model/lib/python3.11/site-packages/wandb/sdk/internal/internal_api.py", line 369, in execute
    return self.client.execute(*args, **kwargs)  # type: ignore
           ^^^^^^^^^^^^^^^^^^^^^^^^^^^^^^^^^^^^
  File "/home/ncclab/miniconda3/envs/att_model/lib/python3.11/site-packages/wandb/vendor/gql-0.2.0/wandb_gql/client.py", line 52, in execute
    result = self._get_result(document, *args, **kwargs)
             ^^^^^^^^^^^^^^^^^^^^^^^^^^^^^^^^^^^^^^^^^^^
  File "/home/ncclab/miniconda3/envs/att_model/lib/python3.11/site-packages/wandb/vendor/gql-0.2.0/wandb_gql/client.py", line 60, in _get_result
    return self.transport.execute(document, *args, **kwargs)
           ^^^^^^^^^^^^^^^^^^^^^^^^^^^^^^^^^^^^^^^^^^^^^^^^^
  File "/home/ncclab/miniconda3/envs/att_model/lib/python3.11/site-packages/wandb/sdk/lib/gql_request.py", line 58, in execute
    request = self.session.post(self.url, **post_args)
              ^^^^^^^^^^^^^^^^^^^^^^^^^^^^^^^^^^^^^^^^
  File "/home/ncclab/miniconda3/envs/att_model/lib/python3.11/site-packages/requests/sessions.py", line 637, in post
    return self.request("POST", url, data=data, json=json, **kwargs)
           ^^^^^^^^^^^^^^^^^^^^^^^^^^^^^^^^^^^^^^^^^^^^^^^^^^^^^^^^^
  File "/home/ncclab/miniconda3/envs/att_model/lib/python3.11/site-packages/requests/sessions.py", line 589, in request
    resp = self.send(prep, **send_kwargs)
           ^^^^^^^^^^^^^^^^^^^^^^^^^^^^^^
  File "/home/ncclab/miniconda3/envs/att_model/lib/python3.11/site-packages/requests/sessions.py", line 703, in send
    r = adapter.send(request, **kwargs)
        ^^^^^^^^^^^^^^^^^^^^^^^^^^^^^^^
  File "/home/ncclab/miniconda3/envs/att_model/lib/python3.11/site-packages/requests/adapters.py", line 532, in send
    raise ReadTimeout(e, request=request)
requests.exceptions.ReadTimeout: HTTPSConnectionPool(host='api.wandb.ai', port=443): Read timed out. (read timeout=20)
2024-05-14 16:43:48,824 DEBUG   HandlerThread:29835 [handler.py:handle_request():146] handle_request: keepalive
2024-05-14 16:43:53,828 DEBUG   HandlerThread:29835 [handler.py:handle_request():146] handle_request: keepalive
2024-05-14 16:43:58,831 DEBUG   HandlerThread:29835 [handler.py:handle_request():146] handle_request: keepalive
2024-05-14 16:44:03,834 DEBUG   HandlerThread:29835 [handler.py:handle_request():146] handle_request: keepalive
2024-05-14 16:44:08,837 DEBUG   HandlerThread:29835 [handler.py:handle_request():146] handle_request: keepalive
2024-05-14 16:44:13,840 DEBUG   HandlerThread:29835 [handler.py:handle_request():146] handle_request: cancel
2024-05-14 16:44:13,840 DEBUG   HandlerThread:29835 [handler.py:handle_request():146] handle_request: cancel
2024-05-14 16:44:13,841 DEBUG   SenderThread:29835 [sender.py:send():388] Record cancelled: run
2024-05-14 16:44:13,841 DEBUG   HandlerThread:29835 [handler.py:handle_request():146] handle_request: status_report
2024-05-14 16:44:14,133 DEBUG   HandlerThread:29835 [handler.py:handle_request():146] handle_request: shutdown
2024-05-14 16:44:14,133 INFO    HandlerThread:29835 [handler.py:finish():866] shutting down handler
2024-05-14 16:44:14,842 INFO    SenderThread:29835 [sender.py:finish():1546] shutting down sender
2024-05-14 16:44:14,842 INFO    WriterThread:29835 [datastore.py:close():296] close: ./wandb/run-20240514_164243-kaofva3p/run-kaofva3p.wandb
