2024-05-17 18:25:16,206 INFO    StreamThr :131556 [internal.py:wandb_internal():86] W&B internal server running at pid: 131556, started at: 2024-05-17 18:25:16.205181
2024-05-17 18:25:16,209 DEBUG   HandlerThread:131556 [handler.py:handle_request():146] handle_request: status
2024-05-17 18:25:16,213 INFO    WriterThread:131556 [datastore.py:open_for_write():87] open: ./wandb/run-20240517_182516-jnz6vggq/run-jnz6vggq.wandb
2024-05-17 18:25:16,213 DEBUG   SenderThread:131556 [sender.py:send():379] send: header
2024-05-17 18:25:16,215 DEBUG   SenderThread:131556 [sender.py:send():379] send: run
2024-05-17 18:25:16,219 INFO    SenderThread:131556 [sender.py:_setup_resume():749] checking resume status for None/SEED_test_loo/jnz6vggq
2024-05-17 18:25:21,218 DEBUG   HandlerThread:131556 [handler.py:handle_request():146] handle_request: keepalive
2024-05-17 18:25:26,221 DEBUG   HandlerThread:131556 [handler.py:handle_request():146] handle_request: keepalive
2024-05-17 18:25:31,224 DEBUG   HandlerThread:131556 [handler.py:handle_request():146] handle_request: keepalive
2024-05-17 18:25:36,227 DEBUG   HandlerThread:131556 [handler.py:handle_request():146] handle_request: keepalive
2024-05-17 18:25:41,230 DEBUG   HandlerThread:131556 [handler.py:handle_request():146] handle_request: keepalive
2024-05-17 18:25:46,233 DEBUG   HandlerThread:131556 [handler.py:handle_request():146] handle_request: keepalive
2024-05-17 18:25:51,237 DEBUG   HandlerThread:131556 [handler.py:handle_request():146] handle_request: keepalive
2024-05-17 18:25:56,239 DEBUG   HandlerThread:131556 [handler.py:handle_request():146] handle_request: keepalive
2024-05-17 18:26:01,243 DEBUG   HandlerThread:131556 [handler.py:handle_request():146] handle_request: keepalive
2024-05-17 18:26:06,245 DEBUG   HandlerThread:131556 [handler.py:handle_request():146] handle_request: keepalive
2024-05-17 18:26:11,248 DEBUG   HandlerThread:131556 [handler.py:handle_request():146] handle_request: keepalive
2024-05-17 18:26:16,250 DEBUG   HandlerThread:131556 [handler.py:handle_request():146] handle_request: keepalive
2024-05-17 18:26:20,785 INFO    SenderThread:131556 [retry.py:__call__():172] Retry attempt failed:
Traceback (most recent call last):
  File "/home/ncclab/miniconda3/envs/att_model/lib/python3.11/site-packages/urllib3/connection.py", line 203, in _new_conn
    sock = connection.create_connection(
           ^^^^^^^^^^^^^^^^^^^^^^^^^^^^^
  File "/home/ncclab/miniconda3/envs/att_model/lib/python3.11/site-packages/urllib3/util/connection.py", line 85, in create_connection
    raise err
  File "/home/ncclab/miniconda3/envs/att_model/lib/python3.11/site-packages/urllib3/util/connection.py", line 73, in create_connection
    sock.connect(sa)
TimeoutError: timed out

The above exception was the direct cause of the following exception:

Traceback (most recent call last):
  File "/home/ncclab/miniconda3/envs/att_model/lib/python3.11/site-packages/urllib3/connectionpool.py", line 790, in urlopen
    response = self._make_request(
               ^^^^^^^^^^^^^^^^^^^
  File "/home/ncclab/miniconda3/envs/att_model/lib/python3.11/site-packages/urllib3/connectionpool.py", line 491, in _make_request
    raise new_e
  File "/home/ncclab/miniconda3/envs/att_model/lib/python3.11/site-packages/urllib3/connectionpool.py", line 467, in _make_request
    self._validate_conn(conn)
  File "/home/ncclab/miniconda3/envs/att_model/lib/python3.11/site-packages/urllib3/connectionpool.py", line 1096, in _validate_conn
    conn.connect()
  File "/home/ncclab/miniconda3/envs/att_model/lib/python3.11/site-packages/urllib3/connection.py", line 611, in connect
    self.sock = sock = self._new_conn()
                       ^^^^^^^^^^^^^^^^
  File "/home/ncclab/miniconda3/envs/att_model/lib/python3.11/site-packages/urllib3/connection.py", line 212, in _new_conn
    raise ConnectTimeoutError(
urllib3.exceptions.ConnectTimeoutError: (<urllib3.connection.HTTPSConnection object at 0x7fc101cf0890>, 'Connection to api.wandb.ai timed out. (connect timeout=20)')

The above exception was the direct cause of the following exception:

Traceback (most recent call last):
  File "/home/ncclab/miniconda3/envs/att_model/lib/python3.11/site-packages/requests/adapters.py", line 486, in send
    resp = conn.urlopen(
           ^^^^^^^^^^^^^
  File "/home/ncclab/miniconda3/envs/att_model/lib/python3.11/site-packages/urllib3/connectionpool.py", line 844, in urlopen
    retries = retries.increment(
              ^^^^^^^^^^^^^^^^^^
  File "/home/ncclab/miniconda3/envs/att_model/lib/python3.11/site-packages/urllib3/util/retry.py", line 515, in increment
    raise MaxRetryError(_pool, url, reason) from reason  # type: ignore[arg-type]
    ^^^^^^^^^^^^^^^^^^^^^^^^^^^^^^^^^^^^^^^^^^^^^^^^^^^
urllib3.exceptions.MaxRetryError: HTTPSConnectionPool(host='api.wandb.ai', port=443): Max retries exceeded with url: /graphql (Caused by ConnectTimeoutError(<urllib3.connection.HTTPSConnection object at 0x7fc101cf0890>, 'Connection to api.wandb.ai timed out. (connect timeout=20)'))

During handling of the above exception, another exception occurred:

Traceback (most recent call last):
  File "/home/ncclab/miniconda3/envs/att_model/lib/python3.11/site-packages/wandb/sdk/lib/retry.py", line 131, in __call__
    result = self._call_fn(*args, **kwargs)
             ^^^^^^^^^^^^^^^^^^^^^^^^^^^^^^
  File "/home/ncclab/miniconda3/envs/att_model/lib/python3.11/site-packages/wandb/sdk/internal/internal_api.py", line 369, in execute
    return self.client.execute(*args, **kwargs)  # type: ignore
           ^^^^^^^^^^^^^^^^^^^^^^^^^^^^^^^^^^^^
  File "/home/ncclab/miniconda3/envs/att_model/lib/python3.11/site-packages/wandb/vendor/gql-0.2.0/wandb_gql/client.py", line 52, in execute
    result = self._get_result(document, *args, **kwargs)
             ^^^^^^^^^^^^^^^^^^^^^^^^^^^^^^^^^^^^^^^^^^^
  File "/home/ncclab/miniconda3/envs/att_model/lib/python3.11/site-packages/wandb/vendor/gql-0.2.0/wandb_gql/client.py", line 60, in _get_result
    return self.transport.execute(document, *args, **kwargs)
           ^^^^^^^^^^^^^^^^^^^^^^^^^^^^^^^^^^^^^^^^^^^^^^^^^
  File "/home/ncclab/miniconda3/envs/att_model/lib/python3.11/site-packages/wandb/sdk/lib/gql_request.py", line 58, in execute
    request = self.session.post(self.url, **post_args)
              ^^^^^^^^^^^^^^^^^^^^^^^^^^^^^^^^^^^^^^^^
  File "/home/ncclab/miniconda3/envs/att_model/lib/python3.11/site-packages/requests/sessions.py", line 637, in post
    return self.request("POST", url, data=data, json=json, **kwargs)
           ^^^^^^^^^^^^^^^^^^^^^^^^^^^^^^^^^^^^^^^^^^^^^^^^^^^^^^^^^
  File "/home/ncclab/miniconda3/envs/att_model/lib/python3.11/site-packages/requests/sessions.py", line 589, in request
    resp = self.send(prep, **send_kwargs)
           ^^^^^^^^^^^^^^^^^^^^^^^^^^^^^^
  File "/home/ncclab/miniconda3/envs/att_model/lib/python3.11/site-packages/requests/sessions.py", line 703, in send
    r = adapter.send(request, **kwargs)
        ^^^^^^^^^^^^^^^^^^^^^^^^^^^^^^^
  File "/home/ncclab/miniconda3/envs/att_model/lib/python3.11/site-packages/requests/adapters.py", line 507, in send
    raise ConnectTimeout(e, request=request)
requests.exceptions.ConnectTimeout: HTTPSConnectionPool(host='api.wandb.ai', port=443): Max retries exceeded with url: /graphql (Caused by ConnectTimeoutError(<urllib3.connection.HTTPSConnection object at 0x7fc101cf0890>, 'Connection to api.wandb.ai timed out. (connect timeout=20)'))
2024-05-17 18:26:21,253 DEBUG   HandlerThread:131556 [handler.py:handle_request():146] handle_request: keepalive
2024-05-17 18:26:26,257 DEBUG   HandlerThread:131556 [handler.py:handle_request():146] handle_request: keepalive
2024-05-17 18:26:31,260 DEBUG   HandlerThread:131556 [handler.py:handle_request():146] handle_request: keepalive
2024-05-17 18:26:36,263 DEBUG   HandlerThread:131556 [handler.py:handle_request():146] handle_request: keepalive
2024-05-17 18:26:41,266 DEBUG   HandlerThread:131556 [handler.py:handle_request():146] handle_request: keepalive
2024-05-17 18:26:46,269 DEBUG   HandlerThread:131556 [handler.py:handle_request():146] handle_request: cancel
2024-05-17 18:26:46,270 DEBUG   HandlerThread:131556 [handler.py:handle_request():146] handle_request: cancel
2024-05-17 18:26:46,270 DEBUG   SenderThread:131556 [sender.py:send():388] Record cancelled: run
2024-05-17 18:26:46,271 DEBUG   HandlerThread:131556 [handler.py:handle_request():146] handle_request: status_report
2024-05-17 18:26:46,836 DEBUG   HandlerThread:131556 [handler.py:handle_request():146] handle_request: shutdown
2024-05-17 18:26:46,836 INFO    HandlerThread:131556 [handler.py:finish():866] shutting down handler
2024-05-17 18:26:47,271 INFO    SenderThread:131556 [sender.py:finish():1546] shutting down sender
2024-05-17 18:26:47,272 INFO    WriterThread:131556 [datastore.py:close():296] close: ./wandb/run-20240517_182516-jnz6vggq/run-jnz6vggq.wandb
